<?xml version="1.0" encoding="UTF-8"?>
<!-- Generated by org.testng.reporters.JUnitXMLReporter -->
<testsuite ignored="0" hostname="FYNXTLAPIND066" failures="1" tests="1" name="Test(failed)(failed)" time="26.972" errors="0" timestamp="2024-09-20T16:26:37 IST">
  <testcase classname="testCases.TC004_CreateMT4AccountTest" name="createMT4_Account" time="19.04">
    <failure type="java.lang.AssertionError" message="Test failed due to an exception.">
      <![CDATA[java.lang.AssertionError: Test failed due to an exception.
at testCases.TC004_CreateMT4AccountTest.createMT4_Account(TC004_CreateMT4AccountTest.java:67)
at java.base/java.util.ArrayList.forEach(ArrayList.java:1596)
... Removed 26 stack frames]]>
    </failure>
  </testcase> <!-- createMT4_Account -->
</testsuite> <!-- Test(failed)(failed) -->
